<?xml version="1.0" encoding="utf-8"?>
<!-- This URDF was automatically created by SolidWorks to URDF Exporter! Originally created by Stephen Brawner (brawner@gmail.com) 
     Commit Version: 1.6.0-1-g15f4949  Build Version: 1.6.7594.29634
     For more information, please see http://wiki.ros.org/sw_urdf_exporter -->
<robot
  name="mim_arm">
  <link
    name="mim_arm_base_link">
    <inertial>
      <origin
        xyz="4.0324476207476E-19 0.0201017280573514 1.22282880618414E-18"
        rpy="0 0 0" />
      <mass
        value="0.689240659662406" />
      <inertia
        ixx="0.00102434108086272"
        ixy="-4.53910013248264E-22"
        ixz="6.32595764050144E-21"
        iyy="0.00186019972980973"
        iyz="9.14439629641527E-21"
        izz="0.00102434108086272" />
    </inertial>
    <visual>
      <origin
        xyz="0 0 0"
        rpy="0 0 0" />
      <geometry>
        <mesh
          filename="package://mim_arm/meshes/base_link.STL" />
      </geometry>
      <material
        name="">
        <color
          rgba="0.792156862745098 0.819607843137255 0.933333333333333 1" />
      </material>
    </visual>
    <collision>
      <origin
        xyz="0 0 0"
        rpy="0 0 0" />
      <geometry>
        <mesh
          filename="package://mim_arm/meshes/base_link.STL" />
      </geometry>
    </collision>
  </link>
  <link
    name="L1">
    <inertial>
      <origin
        xyz="0.0157111756213877 0.0745368977953079 3.22839210484933E-07"
        rpy="0 0 0" />
      <mass
        value="1.46692841296099" />
      <inertia
        ixx="0.00308011645508256"
        ixy="-0.000280319295179128"
        ixz="-2.73424139909787E-08"
        iyy="0.00284729651643544"
        iyz="-4.13248794120909E-08"
        izz="0.00401457189114322" />
    </inertial>
    <visual>
      <origin
        xyz="0 0 0"
        rpy="0 0 0" />
      <geometry>
        <mesh
          filename="package://mim_arm/meshes/L1.STL" />
      </geometry>
      <material
        name="">
        <color
          rgba="0.792156862745098 0.819607843137255 0.933333333333333 1" />
      </material>
    </visual>
    <collision>
      <origin
        xyz="0 0 0"
        rpy="0 0 0" />
      <geometry>
        <mesh
          filename="package://mim_arm/meshes/L1.STL" />
      </geometry>
    </collision>
  </link>
  <joint
    name="J01"
    type="revolute">
    <origin
      xyz="0 0 0.0413"
      rpy="1.5708 0 0.04868" />
    <parent
      link="mim_arm_base_link" />
    <child
      link="L1" />
    <axis
      xyz="0 1 0" />
    <limit
      lower="-2" upper="2"
      effort="1000"
      velocity="30" />
  </joint>
  <link
    name="L2">
    <inertial>
      <origin
        xyz="0.0839314258067013 0.296691749652629 2.79190101315496E-08"
        rpy="0 0 0" />
      <mass
        value="6.19019805184656" />
      <inertia
        ixx="0.29286382896202"
        ixy="-0.00418366073231934"
        ixz="-3.05995251841367E-07"
        iyy="0.00973882828969972"
        iyz="-1.61849364184279E-08"
        izz="0.294707227874404" />
    </inertial>
    <visual>
      <origin
        xyz="0 0 0"
        rpy="0 0 0" />
      <geometry>
        <mesh
          filename="package://mim_arm/meshes/L2.STL" />
      </geometry>
      <material
        name="">
        <color
          rgba="0.792156862745098 0.819607843137255 0.933333333333333 1" />
      </material>
    </visual>
    <collision>
      <origin
        xyz="0 0 0"
        rpy="0 0 0" />
      <geometry>
        <mesh
          filename="package://mim_arm/meshes/L2.STL" />
      </geometry>
    </collision>
  </link>
  <joint
    name="J12"
    type="revolute">
    <origin
      xyz="0.088339 0.0867 0"
      rpy="-0.90844 0 0" />
    <parent
      link="L1" />
    <child
      link="L2" />
    <axis
      xyz="1 0 0" />
    <limit
      lower="-2" upper="2"
      effort="1000"
      velocity="30" />
  </joint>
  <link
    name="L3">
    <inertial>
      <origin
        xyz="-0.0390411312560744 0.284045295063329 -6.99885338573125E-09"
        rpy="0 0 0" />
      <mass
        value="5.63295829772604" />
      <inertia
        ixx="0.228517974777978"
        ixy="0.000925537461414251"
        ixz="-1.66379515722896E-07"
        iyy="0.00797613784003759"
        iyz="-3.62618215112194E-08"
        izz="0.229295350964244" />
    </inertial>
    <visual>
      <origin
        xyz="0 0 0"
        rpy="0 0 0" />
      <geometry>
        <mesh
          filename="package://mim_arm/meshes/L3.STL" />
      </geometry>
      <material
        name="">
        <color
          rgba="0.792156862745098 0.819607843137255 0.933333333333333 1" />
      </material>
    </visual>
    <collision>
      <origin
        xyz="0 0 0"
        rpy="0 0 0" />
      <geometry>
        <mesh
          filename="package://mim_arm/meshes/L3.STL" />
      </geometry>
    </collision>
  </link>
  <joint
    name="J23"
    type="revolute">
    <origin
      xyz="0 0.6121 0"
      rpy="1.2956 0 0" />
    <parent
      link="L2" />
    <child
      link="L3" />
    <axis
      xyz="1 0 0" />
    <limit
      lower="-2" upper="2"
      effort="1000"
      velocity="30" />
  </joint>
  <link
    name="L4">
    <inertial>
      <origin
        xyz="0.0561524171672954 0.00575851444824127 2.22267610150428E-08"
        rpy="0 0 0" />
      <mass
        value="1.00354593818387" />
      <inertia
        ixx="0.00146767412037819"
        ixy="-9.69729917939629E-06"
        ixz="-7.70871234480699E-11"
        iyy="0.00165814310655602"
        iyz="-2.60399148641413E-10"
        izz="0.00179216037210157" />
    </inertial>
    <visual>
      <origin
        xyz="0 0 0"
        rpy="0 0 0" />
      <geometry>
        <mesh
          filename="package://mim_arm/meshes/L4.STL" />
      </geometry>
      <material
        name="">
        <color
          rgba="0.792156862745098 0.819607843137255 0.933333333333333 1" />
      </material>
    </visual>
    <collision>
      <origin
        xyz="0 0 0"
        rpy="0 0 0" />
      <geometry>
        <mesh
          filename="package://mim_arm/meshes/L4.STL" />
      </geometry>
    </collision>
  </link>
  <joint
    name="J34"
    type="revolute">
    <origin
      xyz="0.017974 0.5722 0"
      rpy="-0.59994 0 0" />
    <parent
      link="L3" />
    <child
      link="L4" />
    <axis
      xyz="1 0 0" />
    <limit
      lower="-2" upper="2"
      effort="1000"
      velocity="30" />
  </joint>
  <link
    name="L5">
    <inertial>
      <origin
        xyz="0.0427941745372498 0.0490036715631024 -2.33980786690235E-08"
        rpy="0 0 0" />
      <mass
        value="1.70333973838367" />
      <inertia
        ixx="0.00250547799197183"
        ixy="-9.58300421347055E-05"
        ixz="-1.75039188279538E-09"
        iyy="0.00348668671540668"
        iyz="-2.78336173577817E-05"
        izz="0.00347783620626748" />
    </inertial>
    <visual>
      <origin
        xyz="0 0 0"
        rpy="0 0 0" />
      <geometry>
        <mesh
          filename="package://mim_arm/meshes/L5.STL" />
      </geometry>
      <material
        name="">
        <color
          rgba="0.792156862745098 0.819607843137255 0.933333333333333 1" />
      </material>
    </visual>
    <collision>
      <origin
        xyz="0 0 0"
        rpy="0 0 0" />
      <geometry>
        <mesh
          filename="package://mim_arm/meshes/L5.STL" />
      </geometry>
    </collision>
  </link>
  <joint
    name="J45"
    type="revolute">
    <origin
      xyz="0.057831 0.063304 0"
      rpy="0 -0.00010935 0" />
    <parent
      link="L4" />
    <child
      link="L5" />
    <axis
      xyz="0 1 0" />
    <limit
      lower="-2" upper="2"
      effort="1000"
      velocity="30" />
  </joint>
  <link
    name="GR">
    <inertial>
      <origin
        xyz="0.0273459250494344 2.13762341161328E-12 -3.96627175547337E-13"
        rpy="0 0 0" />
      <mass
        value="0.437864913697669" />
      <inertia
        ixx="0.000703498286069566"
        ixy="-1.44675573672298E-14"
        ixz="7.42004588739735E-15"
        iyy="0.000536785327777073"
        iyz="5.89080786103993E-14"
        izz="0.000377025648223833" />
    </inertial>
    <visual>
      <origin
        xyz="0 0 0"
        rpy="0 0 0" />
      <geometry>
        <mesh
          filename="package://mim_arm/meshes/GR.STL" />
      </geometry>
      <material
        name="">
        <color
          rgba="0.792156862745098 0.819607843137255 0.933333333333333 1" />
      </material>
    </visual>
    <collision>
      <origin
        xyz="0 0 0"
        rpy="0 0 0" />
      <geometry>
        <mesh
          filename="package://mim_arm/meshes/GR.STL" />
      </geometry>
    </collision>
  </link>
  <joint
    name="J5G"
    type="fixed">
    <origin
      xyz="0.0912 0.052396 0"
      rpy="-0.17795 0 0" />
    <parent
      link="L5" />
    <child
      link="GR" />
    <axis
      xyz="0 0 0" />
  </joint>
  <link
    name="G1">
    <inertial>
      <origin
        xyz="0.0284421452977442 0.0100000000000002 0.0186690552507071"
        rpy="0 0 0" />
      <mass
        value="0.0483522534480086" />
      <inertia
        ixx="8.82032469824889E-06"
        ixy="-7.26330752270563E-20"
        ixz="6.48121610168242E-06"
        iyy="5.66268780083E-05"
        iyz="-1.6940658945086E-20"
        izz="5.14050368732517E-05" />
    </inertial>
    <visual>
      <origin
        xyz="0 0 0"
        rpy="0 0 0" />
      <geometry>
        <mesh
          filename="package://mim_arm/meshes/G1.STL" />
      </geometry>
      <material
        name="">
        <color
          rgba="0.792156862745098 0.819607843137255 0.933333333333333 1" />
      </material>
    </visual>
    <collision>
      <origin
        xyz="0 0 0"
        rpy="0 0 0" />
      <geometry>
        <mesh
          filename="package://mim_arm/meshes/G1.STL" />
      </geometry>
    </collision>
  </link>
  <joint
    name="GJ1"
    type="prismatic">
    <origin
      xyz="0.055 -0.01 0"
      rpy="0 0 0" />
    <parent
      link="GR" />
    <child
      link="G1" />
    <axis
      xyz="0 0 1" />
    <limit
      lower="0"
      upper="0.04"
      effort="100"
      velocity="30" />
  </joint>

  <link
    name="G2">
    <inertial>
      <origin
        xyz="0.0284421452977444 -0.00999999999999934 0.0316457779523832" 
        rpy="0 0 0" />
      <mass
        value="0.0483522534480086" />
      <inertia
        ixx="8.82032469824892E-06"
        ixy="1.29490161811501E-19"
        ixz="6.48121610168246E-06"
        iyy="5.66268780083E-05"
        iyz="-3.3881317890172E-20"
        izz="5.14050368732517E-05" />
    </inertial>
    <visual>
      <origin
        xyz="0 0 0"
        rpy="0 0 0" />
      <geometry>
        <mesh
          filename="package://mim_arm/meshes/G2.STL" />
      </geometry>
      <material
        name="">
        <color
          rgba="0.792156862745098 0.819607843137255 0.933333333333333 1" />
      </material>
    </visual>
    <collision>
      <origin
        xyz="0 0 0"
        rpy="0 0 0" />
      <geometry>
        <mesh
          filename="package://mim_arm/meshes/G2.STL" />
      </geometry>
    </collision>
  </link>
  <joint
    name="GJ2"
    type="prismatic">
    <origin
      xyz="0.055 -0.01 0"
      rpy="-3.1416 0 0" />
    <parent
      link="GR" />
    <child
      link="G2" />
    <axis
      xyz="0 0 1" />
    <limit
      lower="0"
      upper="0.04"
      effort="100"
      velocity="30" />
  </joint>
</robot>
