<?xml version="1.0" encoding="utf-8"?>
<!-- This URDF was automatically created by SolidWorks to URDF Exporter! Originally created by Stephen Brawner (brawner@gmail.com) 
     Commit Version: 1.6.0-1-g15f4949  Build Version: 1.6.7594.29634
     For more information, please see http://wiki.ros.org/sw_urdf_exporter -->
<robot
  name="mim_rockerb">
  <link
    name="base_link">
    <inertial>
      <origin
        xyz="-0.115677345952096 -0.00101374975812835 0.184699133480931"
        rpy="0 0 0" />
      <mass
        value="0.858306725756551" />
      <inertia
        ixx="0.00562714308276403"
        ixy="-5.78370242802336E-17"
        ixz="-0.000265893821689072"
        iyy="0.0122556900176676"
        iyz="1.92728266798107E-17"
        izz="0.0177117373798651" />
    </inertial>
    <visual>
      <origin
        xyz="0 0 0"
        rpy="0 0 0" />
      <geometry>
        <mesh
          filename="package://mim_rockerb/meshes/base_link.STL" />
      </geometry>
      <material
        name="">
        <color
          rgba="0.792156862745098 0.819607843137255 0.933333333333333 1" />
      </material>
    </visual>
    <collision>
      <origin
        xyz="0 0 0"
        rpy="0 0 0" />
      <geometry>
        <mesh
          filename="package://mim_rockerb/meshes/base_link.STL" />
      </geometry>
    </collision>
  </link>
  <link
    name="B1">
    <inertial>
      <origin
        xyz="0.0999674690477277 -0.0361131348896797 -0.113641573438832"
        rpy="0 0 0" />
      <mass
        value="0.53077264293737" />
      <inertia
        ixx="0.000527824522706431"
        ixy="-7.5201190267607E-19"
        ixz="-1.07866200684231E-18"
        iyy="0.00244511022290894"
        iyz="-3.92188750880976E-06"
        izz="0.00222579731791319" />
    </inertial>
    <visual>
      <origin
        xyz="0 0 0"
        rpy="0 0 0" />
      <geometry>
        <mesh
          filename="package://mim_rockerb/meshes/B1.STL" />
      </geometry>
      <material
        name="">
        <color
          rgba="0.792156862745098 0.819607843137255 0.933333333333333 1" />
      </material>
    </visual>
    <collision>
      <origin
        xyz="0 0 0"
        rpy="0 0 0" />
      <geometry>
        <mesh
          filename="package://mim_rockerb/meshes/B1.STL" />
      </geometry>
    </collision>
  </link>
  <joint
    name="b1_j"
    type="continuous">
    <origin
      xyz="0.158749999999997 -0.0785137497581306 0.14499999999999"
      rpy="1.5707963267949 0 3.14159265358979" />
    <parent
      link="base_link" />
    <child
      link="B1" />
    <axis
      xyz="0 0 1" />
  </joint>
  <link
    name="P1">
    <inertial>
      <origin
        xyz="6.80011602582908E-16 -7.8706537162675E-15 -0.01"
        rpy="0 0 0" />
      <mass
        value="0.0720898510112747" />
      <inertia
        ixx="3.02016940016694E-05"
        ixy="4.44286461820474E-23"
        ixz="1.34334655542233E-22"
        iyy="3.02016940016694E-05"
        iyz="4.07470980183428E-23"
        izz="5.57490232813793E-05" />
    </inertial>
    <visual>
      <origin
        xyz="0 0 0"
        rpy="0 0 0" />
      <geometry>
        <mesh
          filename="package://mim_rockerb/meshes/P1.STL" />
      </geometry>
      <material
        name="">
        <color
          rgba="1 1 1 0.2" />
      </material>
    </visual>
    <collision>
      <origin
        xyz="0 0 0"
        rpy="0 0 0" />
      <geometry>
        <mesh
          filename="package://mim_rockerb/meshes/P1.STL" />
      </geometry>
    </collision>
  </link>
  <joint
    name="p1_j"
    type="continuous">
    <origin
      xyz="0.15875 -0.107499999999992 -0.121999999999999"
      rpy="0 0 -1.5707963267949" />
    <parent
      link="B1" />
    <child
      link="P1" />
    <axis
      xyz="0 0 1" />
  </joint>
  <link
    name="C1">
    <inertial>
      <origin
        xyz="-0.00692686642669871 -0.0299432222383514 -8.13408648769887E-09"
        rpy="0 0 0" />
      <mass
        value="0.0175932153888398" />
      <inertia
        ixx="1.27324338860059E-05"
        ixy="-2.43426200728112E-06"
        ixz="9.66327633571756E-13"
        iyy="5.48719613282638E-06"
        iyz="2.85844566421913E-12"
        izz="1.24634950449503E-05" />
    </inertial>
    <visual>
      <origin
        xyz="0 0 0"
        rpy="0 0 0" />
      <geometry>
        <mesh
          filename="package://mim_rockerb/meshes/C1.STL" />
      </geometry>
      <material
        name="">
        <color
          rgba="1 0.501960784313725 0.501960784313725 1" />
      </material>
    </visual>
    <collision>
      <origin
        xyz="0 0 0"
        rpy="0 0 0" />
      <geometry>
        <mesh
          filename="package://mim_rockerb/meshes/C1.STL" />
      </geometry>
    </collision>
  </link>
  <joint
    name="c1_j"
    type="continuous">
    <origin
      xyz="-0.178750000000004 -0.0209999999999924 -0.0999999999999921"
      rpy="-3.14159265358979 -0.02648661094944 3.14159265358979" />
    <parent
      link="B1" />
    <child
      link="C1" />
    <axis
      xyz="0 1 0" />
  </joint>
  <link
    name="CW1">
    <inertial>
      <origin
        xyz="0 -4.9960036108132E-16 -1.04083408558608E-14"
        rpy="0 0 0" />
      <mass
        value="0.0741004703095722" />
      <inertia
        ixx="3.02888208379289E-05"
        ixy="9.6123278914688E-22"
        ixz="2.00716491450643E-21"
        iyy="3.03603122293902E-05"
        iyz="1.34831343534886E-06"
        izz="5.57177442758839E-05" />
    </inertial>
    <visual>
      <origin
        xyz="0 0 0"
        rpy="0 0 0" />
      <geometry>
        <mesh
          filename="package://mim_rockerb/meshes/CW1.STL" />
      </geometry>
      <material
        name="">
        <color
          rgba="1 1 1 0.2" />
      </material>
    </visual>
    <collision>
      <origin
        xyz="0 0 0"
        rpy="0 0 0" />
      <geometry>
        <mesh
          filename="package://mim_rockerb/meshes/CW1.STL" />
      </geometry>
    </collision>
  </link>
  <joint
    name="cw1_j"
    type="continuous">
    <origin
      xyz="-0.0210069660112558 -0.0864999999999994 0"
      rpy="-3.0886194316909 0 -1.5707963267949" />
    <parent
      link="C1" />
    <child
      link="CW1" />
    <axis
      xyz="0 0.0529484501323336 0.998597246956241" />
  </joint>
  <link
    name="B2">
    <inertial>
      <origin
        xyz="0.0999674690477277 -0.0361131348896779 0.113641573438832"
        rpy="0 0 0" />
      <mass
        value="0.53077264293737" />
      <inertia
        ixx="0.000527824522706431"
        ixy="-4.55008845729206E-19"
        ixz="-1.27846908717707E-18"
        iyy="0.00244511022290894"
        iyz="3.92188750880748E-06"
        izz="0.00222579731791319" />
    </inertial>
    <visual>
      <origin
        xyz="0 0 0"
        rpy="0 0 0" />
      <geometry>
        <mesh
          filename="package://mim_rockerb/meshes/B2.STL" />
      </geometry>
      <material
        name="">
        <color
          rgba="0.792156862745098 0.819607843137255 0.933333333333333 1" />
      </material>
    </visual>
    <collision>
      <origin
        xyz="0 0 0"
        rpy="0 0 0" />
      <geometry>
        <mesh
          filename="package://mim_rockerb/meshes/B2.STL" />
      </geometry>
    </collision>
  </link>
  <joint
    name="b2_j"
    type="continuous">
    <origin
      xyz="0.158749999999999 0.0764862502418763 0.14499999999999"
      rpy="1.5707963267949 0 3.14159265358979" />
    <parent
      link="base_link" />
    <child
      link="B2" />
    <axis
      xyz="0 0 1" />
  </joint>
  <link
    name="P2">
    <inertial>
      <origin
        xyz="7.49400541621981E-16 -5.10567517578022E-15 0.0100000000000003"
        rpy="0 0 0" />
      <mass
        value="0.0720898510112747" />
      <inertia
        ixx="3.02016940016694E-05"
        ixy="8.07793566946392E-23"
        ixz="1.34334655542233E-22"
        iyy="3.02016940016694E-05"
        iyz="4.07470980183421E-23"
        izz="5.57490232813793E-05" />
    </inertial>
    <visual>
      <origin
        xyz="0 0 0"
        rpy="0 0 0" />
      <geometry>
        <mesh
          filename="package://mim_rockerb/meshes/P2.STL" />
      </geometry>
      <material
        name="">
        <color
          rgba="1 1 1 0.2" />
      </material>
    </visual>
    <collision>
      <origin
        xyz="0 0 0"
        rpy="0 0 0" />
      <geometry>
        <mesh
          filename="package://mim_rockerb/meshes/P2.STL" />
      </geometry>
    </collision>
  </link>
  <joint
    name="p2_j"
    type="continuous">
    <origin
      xyz="0.15875 -0.107499999999987 0.122000000000001"
      rpy="0 0 -1.5707963267949" />
    <parent
      link="B2" />
    <child
      link="P2" />
    <axis
      xyz="0 0 1" />
  </joint>
  <link
    name="C2">
    <inertial>
      <origin
        xyz="-0.00692686642669299 -0.0299432222383514 -8.1340970348176E-09"
        rpy="0 0 0" />
      <mass
        value="0.0175932153888397" />
      <inertia
        ixx="1.27324338860059E-05"
        ixy="-2.43426200728111E-06"
        ixz="9.66327654271124E-13"
        iyy="5.48719613282634E-06"
        iyz="2.85844571260589E-12"
        izz="1.24634950449502E-05" />
    </inertial>
    <visual>
      <origin
        xyz="0 0 0"
        rpy="0 0 0" />
      <geometry>
        <mesh
          filename="package://mim_rockerb/meshes/C2.STL" />
      </geometry>
      <material
        name="">
        <color
          rgba="1 0.501960784313725 0.501960784313725 1" />
      </material>
    </visual>
    <collision>
      <origin
        xyz="0 0 0"
        rpy="0 0 0" />
      <geometry>
        <mesh
          filename="package://mim_rockerb/meshes/C2.STL" />
      </geometry>
    </collision>
  </link>
  <joint
    name="c2_j"
    type="continuous">
    <origin
      xyz="-0.178749999999998 -0.0209999999999919 0.0999999999999913"
      rpy="-3.14159265358979 -0.02648661094944 3.14159265358979" />
    <parent
      link="B2" />
    <child
      link="C2" />
    <axis
      xyz="0 1 0" />
  </joint>
  <link
    name="CW2">
    <inertial>
      <origin
        xyz="0 1.11022302462516E-16 2.44249065417534E-15"
        rpy="0 0 0" />
      <mass
        value="0.0741004703095722" />
      <inertia
        ixx="3.02888208379289E-05"
        ixy="3.76486624506558E-23"
        ixz="2.52750212524786E-21"
        iyy="3.03603122293902E-05"
        iyz="1.34831343534886E-06"
        izz="5.57177442758839E-05" />
    </inertial>
    <visual>
      <origin
        xyz="0 0 0"
        rpy="0 0 0" />
      <geometry>
        <mesh
          filename="package://mim_rockerb/meshes/CW2.STL" />
      </geometry>
      <material
        name="">
        <color
          rgba="0.109803921568627 0.109803921568627 0.109803921568627 1" />
      </material>
    </visual>
    <collision>
      <origin
        xyz="0 0 0"
        rpy="0 0 0" />
      <geometry>
        <mesh
          filename="package://mim_rockerb/meshes/CW2.STL" />
      </geometry>
    </collision>
  </link>
  <joint
    name="cw2_j"
    type="continuous">
    <origin
      xyz="-0.0210069660112499 -0.0864999999999993 0"
      rpy="-3.0886194316909 0 -1.5707963267949" />
    <parent
      link="C2" />
    <child
      link="CW2" />
    <axis
      xyz="0 0.0529484501323336 0.998597246956241" />
  </joint>
  <link
    name="C3">
    <inertial>
      <origin
        xyz="-0.00692686642669293 0.0635846418066492 -8.13409700706202E-09"
        rpy="0 0 0" />
      <mass
        value="0.0175932153888398" />
      <inertia
        ixx="1.27324338860059E-05"
        ixy="-2.43426200728113E-06"
        ixz="9.66327658506288E-13"
        iyy="5.48719613282638E-06"
        iyz="2.85844571386321E-12"
        izz="1.24634950449503E-05" />
    </inertial>
    <visual>
      <origin
        xyz="0 0 0"
        rpy="0 0 0" />
      <geometry>
        <mesh
          filename="package://mim_rockerb/meshes/C3.STL" />
      </geometry>
      <material
        name="">
        <color
          rgba="1 0.501960784313725 0.501960784313725 1" />
      </material>
    </visual>
    <collision>
      <origin
        xyz="0 0 0"
        rpy="0 0 0" />
      <geometry>
        <mesh
          filename="package://mim_rockerb/meshes/C3.STL" />
      </geometry>
    </collision>
  </link>
  <joint
    name="c3_j"
    type="continuous">
    <origin
      xyz="-0.337499999999998 0.176486250241871 0.0304721359549893"
      rpy="1.57079632679489 0 0.0264866109494337" />
    <parent
      link="base_link" />
    <child
      link="C3" />
    <axis
      xyz="0 1 0" />
  </joint>
  <link
    name="CW3">
    <inertial>
      <origin
        xyz="-1.38777878078145E-17 0 -8.32667268468867E-17"
        rpy="0 0 0" />
      <mass
        value="0.0741004703095721" />
      <inertia
        ixx="3.02888208379289E-05"
        ixy="1.77029776998244E-21"
        ixz="2.25034416444156E-21"
        iyy="3.03603122293902E-05"
        iyz="1.34831343534886E-06"
        izz="5.57177442758839E-05" />
    </inertial>
    <visual>
      <origin
        xyz="0 0 0"
        rpy="0 0 0" />
      <geometry>
        <mesh
          filename="package://mim_rockerb/meshes/CW3.STL" />
      </geometry>
      <material
        name="">
        <color
          rgba="1 1 1 0.2" />
      </material>
    </visual>
    <collision>
      <origin
        xyz="0 0 0"
        rpy="0 0 0" />
      <geometry>
        <mesh
          filename="package://mim_rockerb/meshes/CW3.STL" />
      </geometry>
    </collision>
  </link>
  <joint
    name="cw3_j"
    type="continuous">
    <origin
      xyz="-0.02100696601125 0.00702786404500043 0"
      rpy="-3.0886194316909 0 -1.5707963267949" />
    <parent
      link="C3" />
    <child
      link="CW3" />
    <axis
      xyz="0 0.0529484501323336 0.998597246956241" />
  </joint>
  <link
    name="C4">
    <inertial>
      <origin
        xyz="-0.00692686642669288 0.063584641806649 -8.13409695155087E-09"
        rpy="0 0 0" />
      <mass
        value="0.0175932153888396" />
      <inertia
        ixx="1.27324338860058E-05"
        ixy="-2.43426200728109E-06"
        ixz="9.6632765231236E-13"
        iyy="5.48719613282633E-06"
        iyz="2.85844570629285E-12"
        izz="1.24634950449502E-05" />
    </inertial>
    <visual>
      <origin
        xyz="0 0 0"
        rpy="0 0 0" />
      <geometry>
        <mesh
          filename="package://mim_rockerb/meshes/C4.STL" />
      </geometry>
      <material
        name="">
        <color
          rgba="1 0.501960784313725 0.501960784313725 1" />
      </material>
    </visual>
    <collision>
      <origin
        xyz="0 0 0"
        rpy="0 0 0" />
      <geometry>
        <mesh
          filename="package://mim_rockerb/meshes/C4.STL" />
      </geometry>
    </collision>
  </link>
  <joint
    name="c4_j"
    type="continuous">
    <origin
      xyz="-0.337500000000003 -0.178513749758129 0.0304699999999907"
      rpy="1.57079632679489 0 0.0264866109494337" />
    <parent
      link="base_link" />
    <child
      link="C4" />
    <axis
      xyz="0 1 0" />
  </joint>
  <link
    name="CW4">
    <inertial>
      <origin
        xyz="0 -5.55111512312578E-17 -2.4980018054066E-16"
        rpy="0 0 0" />
      <mass
        value="0.0741004703095722" />
      <inertia
        ixx="3.02888208379289E-05"
        ixy="7.00422945090931E-22"
        ixz="1.98417565024643E-21"
        iyy="3.03603122293902E-05"
        iyz="1.34831343534886E-06"
        izz="5.57177442758839E-05" />
    </inertial>
    <visual>
      <origin
        xyz="0 0 0"
        rpy="0 0 0" />
      <geometry>
        <mesh
          filename="package://mim_rockerb/meshes/CW4.STL" />
      </geometry>
      <material
        name="">
        <color
          rgba="0.109803921568627 0.109803921568627 0.109803921568627 1" />
      </material>
    </visual>
    <collision>
      <origin
        xyz="0 0 0"
        rpy="0 0 0" />
      <geometry>
        <mesh
          filename="package://mim_rockerb/meshes/CW4.STL" />
      </geometry>
    </collision>
  </link>
  <joint
    name="cw4_j"
    type="continuous">
    <origin
      xyz="-0.02100696601125 0.00702786404500066 0"
      rpy="-3.0886194316909 0 -1.5707963267949" />
    <parent
      link="C4" />
    <child
      link="CW4" />
    <axis
      xyz="0 0.0529484501323336 0.998597246956241" />
  </joint>
</robot>
