<?xml version="1.0" encoding="utf-8"?>
<!-- This URDF was automatically created by SolidWorks to URDF Exporter! Originally created by Stephen Brawner (brawner@gmail.com) 
     Commit Version: 1.6.0-1-g15f4949  Build Version: 1.6.7594.29634
     For more information, please see http://wiki.ros.org/sw_urdf_exporter -->
<robot
  name="mim_rockerb">
  <link
    name="base_link">
    <inertial>
      <origin
        xyz="-0.0310750411039088 -0.00101374975813606 0.238160967766868"
        rpy="0 0 0" />
      <mass
        value="24.5477793824158" />
      <inertia
        ixx="0.424952095698885"
        ixy="1.10780566636945E-14"
        ixz="-0.00207397180917225"
        iyy="0.949637739801501"
        iyz="-2.54609920500575E-16"
        izz="1.35600296920664" />
    </inertial>
    <visual>
      <origin
        xyz="0 0 0"
        rpy="0 0 0" />
      <geometry>
        <mesh
          filename="package://mim_robots/meshes/rockerb/base_link.STL" />
      </geometry>
      <material
        name="">
        <color
          rgba="0.529411764705882 0.549019607843137 0.549019607843137 1" />
      </material>
    </visual>
    <collision>
      <origin
        xyz="0 0 0"
        rpy="0 0 0" />
      <geometry>
        <mesh
          filename="package://mim_robots/meshes/rockerb/base_link.STL" />
      </geometry>
    </collision>
  </link>
  <link
    name="B1">
    <inertial>
      <origin
        xyz="0.100235231582522 -0.0361286147008293 -0.113654678832962"
        rpy="0 0 0" />
      <mass
        value="4.13605312852322" />
      <inertia
        ixx="0.0041169709377967"
        ixy="-2.41050473724805E-14"
        ixz="5.06991297414661E-17"
        iyy="0.019071816222605"
        iyz="-3.05907225686968E-05"
        izz="0.0173611587404094" />
    </inertial>
    <visual>
      <origin
        xyz="0 0 0"
        rpy="0 0 0" />
      <geometry>
        <mesh
          filename="package://mim_robots/meshes/rockerb/B1.STL" />
      </geometry>
      <material
        name="">
        <color
          rgba="0.529411764705882 0.549019607843137 0.549019607843137 1" />
      </material>
    </visual>
    <collision>
      <origin
        xyz="0 0 0"
        rpy="0 0 0" />
      <geometry>
        <mesh
          filename="package://mim_robots/meshes/rockerb/B1.STL" />
      </geometry>
    </collision>
  </link>
  <joint
    name="B1_J"
    type="continuous">
    <origin
      xyz="0.158749999999996 -0.0785137497581288 0.144999999999991"
      rpy="1.57079632679489 0 -3.14159265358979" />
    <parent
      link="base_link" />
    <child
      link="B1" />
    <axis
      xyz="0 0 1" />
  </joint>
  <link
    name="P1">
    <inertial>
      <origin
        xyz="7.21644966006352E-16 2.0792882191223E-13 -0.0100000000000031"
        rpy="0 0 0" />
      <mass
        value="0.0720898510112747" />
      <inertia
        ixx="3.02016940016694E-05"
        ixy="5.16987882845642E-23"
        ixz="1.27359215146698E-22"
        iyy="3.02016940016694E-05"
        iyz="2.57070454816238E-23"
        izz="5.57490232813793E-05" />
    </inertial>
    <visual>
      <origin
        xyz="0 0 0"
        rpy="0 0 0" />
      <geometry>
        <mesh
          filename="package://mim_robots/meshes/rockerb/P1.STL" />
      </geometry>
      <material
        name="">
        <color
          rgba="1 1 1 0.2" />
      </material>
    </visual>
    <collision>
      <origin
        xyz="0 0 0"
        rpy="0 0 0" />
      <geometry>
        <mesh
          filename="package://mim_robots/meshes/rockerb/P1.STL" />
      </geometry>
    </collision>
  </link>
  <joint
    name="P1_J"
    type="continuous">
    <origin
      xyz="0.15875 -0.107499999999674 -0.122"
      rpy="0 0 -1.5707963267949" />
    <parent
      link="B1" />
    <child
      link="P1" />
    <axis
      xyz="0 0 1" />
  </joint>
  <link
    name="C1">
    <inertial>
      <origin
        xyz="-0.00692686642675311 -0.0299432222383374 -8.13409459232695E-09"
        rpy="0 0 0" />
      <mass
        value="0.13722708003295" />
      <inertia
        ixx="9.93129843107701E-05"
        ixy="-1.89872436569062E-05"
        ixz="7.53735564122841E-12"
        iyy="4.28001298361218E-05"
        iyz="2.22958763209591E-11"
        izz="9.72152613506119E-05" />
    </inertial>
    <visual>
      <origin
        xyz="0 0 0"
        rpy="0 0 0" />
      <geometry>
        <mesh
          filename="package://mim_robots/meshes/rockerb/C1.STL" />
      </geometry>
      <material
        name="">
        <color
          rgba="0.529411764705882 0.549019607843137 0.549019607843137 1" />
      </material>
    </visual>
    <collision>
      <origin
        xyz="0 0 0"
        rpy="0 0 0" />
      <geometry>
        <mesh
          filename="package://mim_robots/meshes/rockerb/C1.STL" />
      </geometry>
    </collision>
  </link>
  <joint
    name="C1_J"
    type="continuous">
    <origin
      xyz="-0.178749999999958 -0.0210000000003531 -0.100000000000004"
      rpy="-3.14159265358973 -0.026486610949433 3.14159265358979" />
    <parent
      link="B1" />
    <child
      link="C1" />
    <axis
      xyz="0 1 0" />
  </joint>
  <link
    name="CW1">
    <inertial>
      <origin
        xyz="2.75890421619351E-14 8.21565038222616E-15 -2.02615701994091E-15"
        rpy="0 0 0" />
      <mass
        value="0.0741004703095722" />
      <inertia
        ixx="3.02888208379289E-05"
        ixy="1.76220527240161E-22"
        ixz="2.51174769126063E-21"
        iyy="3.03603122293902E-05"
        iyz="1.34831343534886E-06"
        izz="5.57177442758839E-05" />
    </inertial>
    <visual>
      <origin
        xyz="0 0 0"
        rpy="0 0 0" />
      <geometry>
        <mesh
          filename="package://mim_robots/meshes/rockerb/CW1.STL" />
      </geometry>
      <material
        name="">
        <color
          rgba="1 1 1 0.2" />
      </material>
    </visual>
    <collision>
      <origin
        xyz="0 0 0"
        rpy="0 0 0" />
      <geometry>
        <mesh
          filename="package://mim_robots/meshes/rockerb/CW1.STL" />
      </geometry>
    </collision>
  </link>
  <joint
    name="CW1_J"
    type="continuous">
    <origin
      xyz="-0.0210069660114238 -0.0864999999999466 0"
      rpy="-3.0886194316909 0 -1.5707963267949" />
    <parent
      link="C1" />
    <child
      link="CW1" />
    <axis
      xyz="0 0.0529484501323336 0.998597246956241" />
  </joint>
  <link
    name="B2">
    <inertial>
      <origin
        xyz="0.10023523158244 -0.0361286147010263 0.113654678832957"
        rpy="0 0 0" />
      <mass
        value="4.13605312852322" />
      <inertia
        ixx="0.0041169709377967"
        ixy="-3.35274558825134E-18"
        ixz="-9.94280947026617E-18"
        iyy="0.0190718162226049"
        iyz="3.05907225686985E-05"
        izz="0.0173611587404094" />
    </inertial>
    <visual>
      <origin
        xyz="0 0 0"
        rpy="0 0 0" />
      <geometry>
        <mesh
          filename="package://mim_robots/meshes/rockerb/B2.STL" />
      </geometry>
      <material
        name="">
        <color
          rgba="0.529411764705882 0.549019607843137 0.549019607843137 1" />
      </material>
    </visual>
    <collision>
      <origin
        xyz="0 0 0"
        rpy="0 0 0" />
      <geometry>
        <mesh
          filename="package://mim_robots/meshes/rockerb/B2.STL" />
      </geometry>
    </collision>
  </link>
  <joint
    name="B2_J"
    type="continuous">
    <origin
      xyz="0.158749999999999 0.0764862502418753 0.144999999999991"
      rpy="1.5707963267949 0 3.14159265358979" />
    <parent
      link="base_link" />
    <child
      link="B2" />
    <axis
      xyz="0 0 1" />
  </joint>
  <link
    name="P2">
    <inertial>
      <origin
        xyz="8.32667268468867E-16 -1.68497409166989E-14 0.0100000000000003"
        rpy="0 0 0" />
      <mass
        value="0.0720898510112747" />
      <inertia
        ixx="3.02016940016694E-05"
        ixy="5.87669819953445E-23"
        ixz="1.27359215146698E-22"
        iyy="3.02016940016694E-05"
        iyz="2.57070454816238E-23"
        izz="5.57490232813793E-05" />
    </inertial>
    <visual>
      <origin
        xyz="0 0 0"
        rpy="0 0 0" />
      <geometry>
        <mesh
          filename="package://mim_robots/meshes/rockerb/P2.STL" />
      </geometry>
      <material
        name="">
        <color
          rgba="1 1 1 0.2" />
      </material>
    </visual>
    <collision>
      <origin
        xyz="0 0 0"
        rpy="0 0 0" />
      <geometry>
        <mesh
          filename="package://mim_robots/meshes/rockerb/P2.STL" />
      </geometry>
    </collision>
  </link>
  <joint
    name="P2_J"
    type="continuous">
    <origin
      xyz="0.15875 -0.107499999999987 0.122000000000001"
      rpy="0 0 -1.5707963267949" />
    <parent
      link="B2" />
    <child
      link="P2" />
    <axis
      xyz="0 0 1" />
  </joint>
  <link
    name="C2">
    <inertial>
      <origin
        xyz="-0.00692686642668838 -0.0299432222383513 -8.13408762567747E-09"
        rpy="0 0 0" />
      <mass
        value="0.137227080032951" />
      <inertia
        ixx="9.93129843108464E-05"
        ixy="-1.89872436567927E-05"
        ixz="7.53735568556942E-12"
        iyy="4.28001298360459E-05"
        iyz="2.22958765455702E-11"
        izz="9.72152613506122E-05" />
    </inertial>
    <visual>
      <origin
        xyz="0 0 0"
        rpy="0 0 0" />
      <geometry>
        <mesh
          filename="package://mim_robots/meshes/rockerb/C2.STL" />
      </geometry>
      <material
        name="">
        <color
          rgba="0.529411764705882 0.549019607843137 0.549019607843137 1" />
      </material>
    </visual>
    <collision>
      <origin
        xyz="0 0 0"
        rpy="0 0 0" />
      <geometry>
        <mesh
          filename="package://mim_robots/meshes/rockerb/C2.STL" />
      </geometry>
    </collision>
  </link>
  <joint
    name="C2_J"
    type="continuous">
    <origin
      xyz="-0.178749999999998 -0.0209999999999919 0.0999999999999913"
      rpy="-3.14159265358979 -0.02648661094944 3.14159265358979" />
    <parent
      link="B2" />
    <child
      link="C2" />
    <axis
      xyz="0 1 0" />
  </joint>
  <link
    name="CW2">
    <inertial>
      <origin
        xyz="4.16333634234434E-17 -5.55111512312578E-17 -2.33146835171283E-15"
        rpy="0 0 0" />
      <mass
        value="0.0741004703095722" />
      <inertia
        ixx="3.02888208379289E-05"
        ixy="1.98439202389641E-21"
        ixz="1.90502309436903E-21"
        iyy="3.03603122293902E-05"
        iyz="1.34831343534886E-06"
        izz="5.57177442758839E-05" />
    </inertial>
    <visual>
      <origin
        xyz="0 0 0"
        rpy="0 0 0" />
      <geometry>
        <mesh
          filename="package://mim_robots/meshes/rockerb/CW2.STL" />
      </geometry>
      <material
        name="">
        <color
          rgba="0.109803921568627 0.109803921568627 0.109803921568627 1" />
      </material>
    </visual>
    <collision>
      <origin
        xyz="0 0 0"
        rpy="0 0 0" />
      <geometry>
        <mesh
          filename="package://mim_robots/meshes/rockerb/CW2.STL" />
      </geometry>
    </collision>
  </link>
  <joint
    name="CW2_J"
    type="continuous">
    <origin
      xyz="-0.0210069660112452 -0.0864999999999993 0"
      rpy="-3.0886194316909 0 -1.5707963267949" />
    <parent
      link="C2" />
    <child
      link="CW2" />
    <axis
      xyz="0 0.0529484501323336 0.998597246956241" />
  </joint>
  <link
    name="C3">
    <inertial>
      <origin
        xyz="-0.00692686642669288 -0.0299432222383512 -8.13409697930645E-09"
        rpy="0 0 0" />
      <mass
        value="0.13722708003295" />
      <inertia
        ixx="9.93129843108461E-05"
        ixy="-1.89872436567928E-05"
        ixz="7.53735574041481E-12"
        iyy="4.28001298360458E-05"
        iyz="2.22958765674871E-11"
        izz="9.7215261350612E-05" />
    </inertial>
    <visual>
      <origin
        xyz="0 0 0"
        rpy="0 0 0" />
      <geometry>
        <mesh
          filename="package://mim_robots/meshes/rockerb/C3.STL" />
      </geometry>
      <material
        name="">
        <color
          rgba="0.529411764705882 0.549019607843137 0.549019607843137 1" />
      </material>
    </visual>
    <collision>
      <origin
        xyz="0 0 0"
        rpy="0 0 0" />
      <geometry>
        <mesh
          filename="package://mim_robots/meshes/rockerb/C3.STL" />
      </geometry>
    </collision>
  </link>
  <joint
    name="C3_J"
    type="continuous">
    <origin
      xyz="-0.3375 0.17648625024187 0.123999999999991"
      rpy="1.5707963267949 0 0.0264866109494337" />
    <parent
      link="base_link" />
    <child
      link="C3" />
    <axis
      xyz="0 1 0" />
  </joint>
  <link
    name="CW3">
    <inertial>
      <origin
        xyz="0 0 -5.55111512312578E-17"
        rpy="0 0 0" />
      <mass
        value="0.0741004703095721" />
      <inertia
        ixx="3.02888208379289E-05"
        ixy="1.74196206213053E-21"
        ixz="2.1949650708904E-21"
        iyy="3.03603122293902E-05"
        iyz="1.34831343534886E-06"
        izz="5.57177442758839E-05" />
    </inertial>
    <visual>
      <origin
        xyz="0 0 0"
        rpy="0 0 0" />
      <geometry>
        <mesh
          filename="package://mim_robots/meshes/rockerb/CW3.STL" />
      </geometry>
      <material
        name="">
        <color
          rgba="1 1 1 0.2" />
      </material>
    </visual>
    <collision>
      <origin
        xyz="0 0 0"
        rpy="0 0 0" />
      <geometry>
        <mesh
          filename="package://mim_robots/meshes/rockerb/CW3.STL" />
      </geometry>
    </collision>
  </link>
  <joint
    name="CW3_J"
    type="continuous">
    <origin
      xyz="-0.02100696601125 -0.0865 0"
      rpy="-3.0886194316909 0 -1.5707963267949" />
    <parent
      link="C3" />
    <child
      link="CW3" />
    <axis
      xyz="0 0.0529484501323336 0.998597246956241" />
  </joint>
  <link
    name="C4">
    <inertial>
      <origin
        xyz="-0.00692686642669293 -0.0299432222383513 -8.13409689603972E-09"
        rpy="0 0 0" />
      <mass
        value="0.13722708003295" />
      <inertia
        ixx="9.9312984310846E-05"
        ixy="-1.89872436567927E-05"
        ixz="7.53735563644151E-12"
        iyy="4.28001298360457E-05"
        iyz="2.2295876347788E-11"
        izz="9.72152613506117E-05" />
    </inertial>
    <visual>
      <origin
        xyz="0 0 0"
        rpy="0 0 0" />
      <geometry>
        <mesh
          filename="package://mim_robots/meshes/rockerb/C4.STL" />
      </geometry>
      <material
        name="">
        <color
          rgba="0.529411764705882 0.549019607843137 0.549019607843137 1" />
      </material>
    </visual>
    <collision>
      <origin
        xyz="0 0 0"
        rpy="0 0 0" />
      <geometry>
        <mesh
          filename="package://mim_robots/meshes/rockerb/C4.STL" />
      </geometry>
    </collision>
  </link>
  <joint
    name="C4_J"
    type="continuous">
    <origin
      xyz="-0.337500000000004 -0.17851374975813 0.12399786404499"
      rpy="1.5707963267949 0 0.0264866109494337" />
    <parent
      link="base_link" />
    <child
      link="C4" />
    <axis
      xyz="0 1 0" />
  </joint>
  <link
    name="CW4">
    <inertial>
      <origin
        xyz="0 -5.55111512312578E-17 0"
        rpy="0 0 0" />
      <mass
        value="0.0741004703095722" />
      <inertia
        ixx="3.02888208379289E-05"
        ixy="1.13551811557222E-21"
        ixz="2.7904226818547E-21"
        iyy="3.03603122293902E-05"
        iyz="1.34831343534886E-06"
        izz="5.57177442758839E-05" />
    </inertial>
    <visual>
      <origin
        xyz="0 0 0"
        rpy="0 0 0" />
      <geometry>
        <mesh
          filename="package://mim_robots/meshes/rockerb/CW4.STL" />
      </geometry>
      <material
        name="">
        <color
          rgba="0.109803921568627 0.109803921568627 0.109803921568627 1" />
      </material>
    </visual>
    <collision>
      <origin
        xyz="0 0 0"
        rpy="0 0 0" />
      <geometry>
        <mesh
          filename="package://mim_robots/meshes/rockerb/CW4.STL" />
      </geometry>
    </collision>
  </link>
  <joint
    name="CW4_J"
    type="continuous">
    <origin
      xyz="-0.0210069660112505 -0.0864999999999983 0"
      rpy="-3.0886194316909 0 -1.5707963267949" />
    <parent
      link="C4" />
    <child
      link="CW4" />
    <axis
      xyz="0 0.0529484501323336 0.998597246956241" />
  </joint>
  <link
    name="LIDAR">
    <inertial>
      <origin
        xyz="0.0121635550249433 -0.028764888574191 0.000482127498249719"
        rpy="0 0 0" />
      <mass
        value="0.0730843681136202" />
      <inertia
        ixx="1.95811927494857E-05"
        ixy="-4.28353547726108E-07"
        ixz="1.03772771795953E-07"
        iyy="4.1417819481871E-05"
        iyz="-9.42527080184659E-09"
        izz="2.41241304659595E-05" />
    </inertial>
    <visual>
      <origin
        xyz="0 0 0"
        rpy="0 0 0" />
      <geometry>
        <mesh
          filename="package://mim_robots/meshes/rockerb/LIDAR.STL" />
      </geometry>
      <material
        name="">
        <color
          rgba="0.752941176470588 0.752941176470588 0.752941176470588 1" />
      </material>
    </visual>
    <collision>
      <origin
        xyz="0 0 0"
        rpy="0 0 0" />
      <geometry>
        <mesh
          filename="package://mim_robots/meshes/rockerb/LIDAR.STL" />
      </geometry>
    </collision>
  </link>
  <joint
    name="LIDAR_J"
    type="fixed">
    <origin
      xyz="0.317603295710605 -0.000963772085933554 0.338499999999593"
      rpy="1.5707963267949 0 3.14159265358979" />
    <parent
      link="base_link" />
    <child
      link="LIDAR" />
    <axis
      xyz="0 0 0" />
  </joint>
</robot>
