<?xml version="1.0" encoding="utf-8"?>
<!-- This URDF was automatically created by SolidWorks to URDF Exporter! Originally created by Stephen Brawner (brawner@gmail.com) 
     Commit Version: 1.6.0-1-g15f4949  Build Version: 1.6.7594.29634
     For more information, please see http://wiki.ros.org/sw_urdf_exporter -->
<robot
  name="mim_diffdrive">
  <link
    name="base_link">
    <inertial>
      <origin
        xyz="-3.9620615595323E-15 -0.00101374975806221 0.172677436190927"
        rpy="0 0 0" />
      <mass
        value="33.5973988123837" />
      <inertia
        ixx="1.01936792689011"
        ixy="-2.87646047555418E-07"
        ixz="-4.13322576029007E-16"
        iyy="2.14070538797161"
        iyz="-2.66613602788427E-16"
        izz="3.05624852691436" />
    </inertial>
    <visual>
      <origin
        xyz="0 0 0"
        rpy="0 0 0" />
      <geometry>
        <mesh
            filename="package://mim_robots/meshes/diffdrive/base_link.STL" />
      </geometry>
      <material
        name="">
        <color
          rgba="0.501960784313725 0.501960784313725 0.501960784313725 0.5" />
      </material>
    </visual>
    <collision>
      <origin
        xyz="0 0 0"
        rpy="0 0 0" />
      <geometry>
        <mesh
            filename="package://mim_robots/meshes/diffdrive/base_link.STL" />
      </geometry>
    </collision>
  </link>
  <link
    name="P1">
    <inertial>
      <origin
        xyz="6.93889390390723E-16 2.01722204816701E-15 0"
        rpy="0 0 0" />
      <mass
        value="0.0720898510112747" />
      <inertia
        ixx="3.02016940016694E-05"
        ixy="7.59325952929537E-23"
        ixz="1.25511395674995E-22"
        iyy="3.02016940016694E-05"
        iyz="4.07470980183427E-23"
        izz="5.57490232813793E-05" />
    </inertial>
    <visual>
      <origin
        xyz="0 0 0"
        rpy="0 0 0" />
      <geometry>
        <mesh
            filename="package://mim_robots/meshes/diffdrive/P1.STL" />
      </geometry>
      <material
        name="">
        <color
          rgba="1 1 1 0.2" />
      </material>
    </visual>
    <collision>
      <origin
        xyz="0 0 0"
        rpy="0 0 0" />
      <geometry>
        <mesh
            filename="package://mim_robots/meshes/diffdrive/P1.STL" />
      </geometry>
    </collision>
  </link>
  <joint
    name="P1_J"
    type="continuous">
    <origin
      xyz="0 -0.210513749758133 0.0375000000000007"
      rpy="1.57079632679489 1.5707963267949 0" />
    <parent
      link="base_link" />
    <child
      link="P1" />
    <axis
      xyz="0 0 1" />
  </joint>
  <link
    name="P2">
    <inertial>
      <origin
        xyz="7.63278329429795E-16 -4.37692422136912E-15 5.55111512312578E-17"
        rpy="0 0 0" />
      <mass
        value="0.0720898510112747" />
      <inertia
        ixx="3.02016940016694E-05"
        ixy="3.39273298117377E-23"
        ixz="1.25511395674995E-22"
        iyy="3.02016940016694E-05"
        iyz="4.07470980183422E-23"
        izz="5.57490232813793E-05" />
    </inertial>
    <visual>
      <origin
        xyz="0 0 0"
        rpy="0 0 0" />
      <geometry>
        <mesh
            filename="package://mim_robots/meshes/diffdrive/P2.STL" />
      </geometry>
      <material
        name="">
        <color
          rgba="1 1 1 0.2" />
      </material>
    </visual>
    <collision>
      <origin
        xyz="0 0 0"
        rpy="0 0 0" />
      <geometry>
        <mesh
            filename="package://mim_robots/meshes/diffdrive/P2.STL" />
      </geometry>
    </collision>
  </link>
  <joint
    name="P2_J"
    type="continuous">
    <origin
      xyz="0 0.208486250241876 0.0375000000000008"
      rpy="1.57079632679489 1.5707963267949 0" />
    <parent
      link="base_link" />
    <child
      link="P2" />
    <axis
      xyz="0 0 1" />
  </joint>
  <link
    name="C1">
    <inertial>
      <origin
        xyz="-0.00692686642669293 0.0635846418066491 -8.13409695155087E-09"
        rpy="0 0 0" />
      <mass
        value="0.13722708003295" />
      <inertia
        ixx="9.93129843108459E-05"
        ixy="-1.89872436567927E-05"
        ixz="7.53735556825536E-12"
        iyy="4.28001298360455E-05"
        iyz="2.2295876374046E-11"
        izz="9.72152613506116E-05" />
    </inertial>
    <visual>
      <origin
        xyz="0 0 0"
        rpy="0 0 0" />
      <geometry>
        <mesh
            filename="package://mim_robots/meshes/diffdrive/C1.STL" />
      </geometry>
      <material
        name="">
        <color
          rgba="0.529411764705882 0.549019607843137 0.549019607843137 1" />
      </material>
    </visual>
    <collision>
      <origin
        xyz="0 0 0"
        rpy="0 0 0" />
      <geometry>
        <mesh
            filename="package://mim_robots/meshes/diffdrive/C1.STL" />
      </geometry>
    </collision>
  </link>
  <joint
    name="C1_J"
    type="continuous">
    <origin
      xyz="0.337499999999999 -0.178513749758134 0.0304721359549996"
      rpy="1.5707963267949 0 0.0264866109494407" />
    <parent
      link="base_link" />
    <child
      link="C1" />
    <axis
      xyz="0 1 0" />
  </joint>
  <link
    name="C1W">
    <inertial>
      <origin
        xyz="0 0 -5.55111512312578E-17"
        rpy="0 0 0" />
      <mass
        value="0.0741004703095722" />
      <inertia
        ixx="3.02888208379289E-05"
        ixy="3.14965690309587E-22"
        ixz="2.24283535816781E-21"
        iyy="3.03603122293902E-05"
        iyz="1.34831343534886E-06"
        izz="5.57177442758839E-05" />
    </inertial>
    <visual>
      <origin
        xyz="0 0 0"
        rpy="0 0 0" />
      <geometry>
        <mesh
            filename="package://mim_robots/meshes/diffdrive/C1W.STL" />
      </geometry>
      <material
        name="">
        <color
          rgba="0.109803921568627 0.109803921568627 0.109803921568627 1" />
      </material>
    </visual>
    <collision>
      <origin
        xyz="0 0 0"
        rpy="0 0 0" />
      <geometry>
        <mesh
            filename="package://mim_robots/meshes/diffdrive/C1W.STL" />
      </geometry>
    </collision>
  </link>
  <joint
    name="C1W_J"
    type="continuous">
    <origin
      xyz="-0.0210069660112502 0.00702786404500044 0"
      rpy="-3.0886194316909 0 -1.5707963267949" />
    <parent
      link="C1" />
    <child
      link="C1W" />
    <axis
      xyz="0 0.0529484501323336 0.998597246956241" />
  </joint>
  <link
    name="C2">
    <inertial>
      <origin
        xyz="-0.00692686642669288 0.0635846418066492 -8.13409700706202E-09"
        rpy="0 0 0" />
      <mass
        value="0.137227080032951" />
      <inertia
        ixx="9.93129843108462E-05"
        ixy="-1.89872436567928E-05"
        ixz="7.53735566248778E-12"
        iyy="4.28001298360458E-05"
        iyz="2.22958766821542E-11"
        izz="9.7215261350612E-05" />
    </inertial>
    <visual>
      <origin
        xyz="0 0 0"
        rpy="0 0 0" />
      <geometry>
        <mesh
            filename="package://mim_robots/meshes/diffdrive/C2.STL" />
      </geometry>
      <material
        name="">
        <color
          rgba="0.529411764705882 0.549019607843137 0.549019607843137 1" />
      </material>
    </visual>
    <collision>
      <origin
        xyz="0 0 0"
        rpy="0 0 0" />
      <geometry>
        <mesh
            filename="package://mim_robots/meshes/diffdrive/C2.STL" />
      </geometry>
    </collision>
  </link>
  <joint
    name="C2_J"
    type="continuous">
    <origin
      xyz="0.337500000000001 0.176486250241866 0.0304721359549995"
      rpy="1.5707963267949 0 0.0264866109494407" />
    <parent
      link="base_link" />
    <child
      link="C2" />
    <axis
      xyz="0 1 0" />
  </joint>
  <link
    name="C2W">
    <inertial>
      <origin
        xyz="-1.38777878078145E-17 0 0"
        rpy="0 0 0" />
      <mass
        value="0.0741004703095722" />
      <inertia
        ixx="3.02888208379289E-05"
        ixy="6.63178656109087E-22"
        ixz="1.96617885959453E-21"
        iyy="3.03603122293902E-05"
        iyz="1.34831343534886E-06"
        izz="5.57177442758839E-05" />
    </inertial>
    <visual>
      <origin
        xyz="0 0 0"
        rpy="0 0 0" />
      <geometry>
        <mesh
            filename="package://mim_robots/meshes/diffdrive/C2W.STL" />
      </geometry>
      <material
        name="">
        <color
          rgba="0.109803921568627 0.109803921568627 0.109803921568627 1" />
      </material>
    </visual>
    <collision>
      <origin
        xyz="0 0 0"
        rpy="0 0 0" />
      <geometry>
        <mesh
            filename="package://mim_robots/meshes/diffdrive/C2W.STL" />
      </geometry>
    </collision>
  </link>
  <joint
    name="C2W_J"
    type="continuous">
    <origin
      xyz="-0.0210069660112502 0.00702786404500046 0"
      rpy="-3.0886194316909 0 -1.5707963267949" />
    <parent
      link="C2" />
    <child
      link="C2W" />
    <axis
      xyz="0 0.0529484501323336 0.998597246956241" />
  </joint>
  <link
    name="C3">
    <inertial>
      <origin
        xyz="-0.00692686642669288 0.063584641806649 -8.13409700706202E-09"
        rpy="0 0 0" />
      <mass
        value="0.137227080032949" />
      <inertia
        ixx="9.93129843108455E-05"
        ixy="-1.89872436567925E-05"
        ixz="7.53735562119492E-12"
        iyy="4.28001298360454E-05"
        iyz="2.22958765094654E-11"
        izz="9.72152613506112E-05" />
    </inertial>
    <visual>
      <origin
        xyz="0 0 0"
        rpy="0 0 0" />
      <geometry>
        <mesh
            filename="package://mim_robots/meshes/diffdrive/C3.STL" />
      </geometry>
      <material
        name="">
        <color
          rgba="0.529411764705882 0.549019607843137 0.549019607843137 1" />
      </material>
    </visual>
    <collision>
      <origin
        xyz="0 0 0"
        rpy="0 0 0" />
      <geometry>
        <mesh
            filename="package://mim_robots/meshes/diffdrive/C3.STL" />
      </geometry>
    </collision>
  </link>
  <joint
    name="C3_J"
    type="continuous">
    <origin
      xyz="-0.337500000000001 -0.178513749758132 0.0304699999999996"
      rpy="1.5707963267949 0 0.0264866109494407" />
    <parent
      link="base_link" />
    <child
      link="C3" />
    <axis
      xyz="0 1 0" />
  </joint>
  <link
    name="C3W">
    <inertial>
      <origin
        xyz="0 -5.55111512312578E-17 -2.4980018054066E-16"
        rpy="0 0 0" />
      <mass
        value="0.0741004703095722" />
      <inertia
        ixx="3.02888208379289E-05"
        ixy="7.32766140857079E-22"
        ixz="1.98493494221899E-21"
        iyy="3.03603122293902E-05"
        iyz="1.34831343534886E-06"
        izz="5.57177442758839E-05" />
    </inertial>
    <visual>
      <origin
        xyz="0 0 0"
        rpy="0 0 0" />
      <geometry>
        <mesh
            filename="package://mim_robots/meshes/diffdrive/C3W.STL" />
      </geometry>
      <material
        name="">
        <color
          rgba="1 1 1 0.2" />
      </material>
    </visual>
    <collision>
      <origin
        xyz="0 0 0"
        rpy="0 0 0" />
      <geometry>
        <mesh
            filename="package://mim_robots/meshes/diffdrive/C3W.STL" />
      </geometry>
    </collision>
  </link>
  <joint
    name="C3W_J"
    type="continuous">
    <origin
      xyz="-0.02100696601125 0.00702786404500066 0"
      rpy="-3.0886194316909 0 -1.5707963267949" />
    <parent
      link="C3" />
    <child
      link="C3W" />
    <axis
      xyz="0 0.0529484501323336 0.998597246956241" />
  </joint>
  <link
    name="C4">
    <inertial>
      <origin
        xyz="-0.00692686642669288 0.0635846418066492 -8.13409697930645E-09"
        rpy="0 0 0" />
      <mass
        value="0.13722708003295" />
      <inertia
        ixx="9.93129843108461E-05"
        ixy="-1.89872436567929E-05"
        ixz="7.53735567222865E-12"
        iyy="4.28001298360458E-05"
        iyz="2.22958765633579E-11"
        izz="9.72152613506121E-05" />
    </inertial>
    <visual>
      <origin
        xyz="0 0 0"
        rpy="0 0 0" />
      <geometry>
        <mesh
            filename="package://mim_robots/meshes/diffdrive/C4.STL" />
      </geometry>
      <material
        name="">
        <color
          rgba="0.529411764705882 0.549019607843137 0.549019607843137 1" />
      </material>
    </visual>
    <collision>
      <origin
        xyz="0 0 0"
        rpy="0 0 0" />
      <geometry>
        <mesh
            filename="package://mim_robots/meshes/diffdrive/C4.STL" />
      </geometry>
    </collision>
  </link>
  <joint
    name="C4_J"
    type="continuous">
    <origin
      xyz="-0.337499999999999 0.176486250241868 0.0304721359549995"
      rpy="1.5707963267949 0 0.0264866109494407" />
    <parent
      link="base_link" />
    <child
      link="C4" />
    <axis
      xyz="0 1 0" />
  </joint>
  <link
    name="C4W">
    <inertial>
      <origin
        xyz="-1.38777878078145E-17 0 -8.32667268468867E-17"
        rpy="0 0 0" />
      <mass
        value="0.0741004703095722" />
      <inertia
        ixx="3.02888208379289E-05"
        ixy="1.74181515086185E-21"
        ixz="2.2504232470915E-21"
        iyy="3.03603122293902E-05"
        iyz="1.34831343534886E-06"
        izz="5.57177442758839E-05" />
    </inertial>
    <visual>
      <origin
        xyz="0 0 0"
        rpy="0 0 0" />
      <geometry>
        <mesh
            filename="package://mim_robots/meshes/diffdrive/C4W.STL" />
      </geometry>
      <material
        name="">
        <color
          rgba="1 1 1 0.2" />
      </material>
    </visual>
    <collision>
      <origin
        xyz="0 0 0"
        rpy="0 0 0" />
      <geometry>
        <mesh
            filename="package://mim_robots/meshes/diffdrive/C4W.STL" />
      </geometry>
    </collision>
  </link>
  <joint
    name="C4W_J"
    type="continuous">
    <origin
      xyz="-0.02100696601125 0.00702786404500043 0"
      rpy="-3.0886194316909 0 -1.5707963267949" />
    <parent
      link="C4" />
    <child
      link="C4W" />
    <axis
      xyz="0 0.0529484501323336 0.998597246956241" />
  </joint>
  <link
    name="LIDAR">
    <inertial>
      <origin
        xyz="0.0121635550237251 -0.0287648885700504 0.000482127519639952"
        rpy="0 0 0" />
      <mass
        value="0.0730843682728084" />
      <inertia
        ixx="1.9581192847151E-05"
        ixy="-4.28353557726989E-07"
        ixz="1.03772853897536E-07"
        iyy="4.14178195715931E-05"
        iyz="-9.42526989362686E-09"
        izz="2.41241304679093E-05" />
    </inertial>
    <visual>
      <origin
        xyz="0 0 0"
        rpy="0 0 0" />
      <geometry>
        <mesh
            filename="package://mim_robots/meshes/diffdrive/LIDAR.STL" />
      </geometry>
      <material
        name="">
        <color
          rgba="0.752941176470588 0.752941176470588 0.752941176470588 1" />
      </material>
    </visual>
    <collision>
      <origin
        xyz="0 0 0"
        rpy="0 0 0" />
      <geometry>
        <mesh
            filename="package://mim_robots/meshes/diffdrive/LIDAR.STL" />
      </geometry>
    </collision>
  </link>
  <joint
    name="LIDAR_J"
    type="fixed">
    <origin
      xyz="0.321103295710635 -0.000963772085875598 0.374500000000008"
      rpy="1.57079632679489 0 -3.14159265358979" />
    <parent
      link="base_link" />
    <child
      link="LIDAR" />
    <axis
      xyz="0 0 0" />
  </joint>
</robot>
